2019-10-30 10:14:42,696 - cmdb - ERROR -log:  Traceback (most recent call last):
  File "E:\wupeiqi\autoclient\lib\plugins\disk.py", line 16, in process
    result = int('asdf')
ValueError: invalid literal for int() with base 10: 'asdf'

2019-10-30 11:24:39,595 - cmdb - ERROR -log:  Traceback (most recent call last):
  File "E:\wupeiqi\autoclient\lib\plugins\disk.py", line 16, in process
    result.data = int('asdf')
ValueError: invalid literal for int() with base 10: 'asdf'

2019-10-30 11:37:13,756 - cmdb - ERROR -log:  Traceback (most recent call last):
  File "E:\wupeiqi\autoclient\lib\plugins\network.py", line 19, in process
    cmd1 = ssh('sudo ip link show')
TypeError: ssh() missing 1 required positional argument: 'cmd'

2019-10-30 11:37:30,455 - cmdb - ERROR -log:  Traceback (most recent call last):
  File "E:\wupeiqi\autoclient\lib\plugins\network.py", line 19, in process
    cmd1 = ssh('sudo ip link show')
TypeError: ssh() missing 1 required positional argument: 'cmd'



2020-02-13 17:02:19,039 - cmdb - ERROR -log:  Traceback (most recent call last):
  File "E:\cmdb\auto_client\lib\plugins\memory.py", line 19, in process
    result = ssh(hostname, 'dmidecode  -q -t 17 2>/dev/null')
  File "E:/cmdb/auto_client/app.py", line 15, in ssh
    ssh.connect(hostname=hostname, port=settings.SSH_PORT, username=settings.SSH_USER, password=settings.SSH_PWD)
  File "E:\Python3\lib\site-packages\paramiko\client.py", line 368, in connect
    raise NoValidConnectionsError(errors)
paramiko.ssh_exception.NoValidConnectionsError: [Errno None] Unable to connect to port 22 on 127.0.0.1

2020-02-13 17:02:22,402 - cmdb - ERROR -log:  Traceback (most recent call last):
  File "E:\cmdb\auto_client\lib\plugins\memory.py", line 19, in process
    result = ssh(hostname, 'dmidecode  -q -t 17 2>/dev/null')
  File "E:/cmdb/auto_client/app.py", line 15, in ssh
    ssh.connect(hostname=hostname, port=settings.SSH_PORT, username=settings.SSH_USER, password=settings.SSH_PWD)
  File "E:\Python3\lib\site-packages\paramiko\client.py", line 368, in connect
    raise NoValidConnectionsError(errors)
paramiko.ssh_exception.NoValidConnectionsError: [Errno None] Unable to connect to port 22 on 127.0.0.1

2020-02-13 17:02:24,466 - cmdb - ERROR -log:  Traceback (most recent call last):
  File "E:\cmdb\auto_client\lib\plugins\network.py", line 19, in process
    cmd1 = ssh(hostname,'sudo ip link show')
  File "E:/cmdb/auto_client/app.py", line 15, in ssh
    ssh.connect(hostname=hostname, port=settings.SSH_PORT, username=settings.SSH_USER, password=settings.SSH_PWD)
  File "E:\Python3\lib\site-packages\paramiko\client.py", line 368, in connect
    raise NoValidConnectionsError(errors)
paramiko.ssh_exception.NoValidConnectionsError: [Errno None] Unable to connect to port 22 on 127.0.0.1

2020-02-13 17:02:26,564 - cmdb - ERROR -log:  Traceback (most recent call last):
  File "E:\cmdb\auto_client\lib\plugins\basic.py", line 13, in process
    uname = ssh(hostname, 'uname').strip()
  File "E:/cmdb/auto_client/app.py", line 15, in ssh
    ssh.connect(hostname=hostname, port=settings.SSH_PORT, username=settings.SSH_USER, password=settings.SSH_PWD)
  File "E:\Python3\lib\site-packages\paramiko\client.py", line 368, in connect
    raise NoValidConnectionsError(errors)
paramiko.ssh_exception.NoValidConnectionsError: [Errno None] Unable to connect to port 22 on 127.0.0.1

2020-02-13 17:02:28,631 - cmdb - ERROR -log:  Traceback (most recent call last):
  File "E:\cmdb\auto_client\lib\plugins\board.py", line 13, in process
    result = ssh(hostname,'dmidecode -t1')
  File "E:/cmdb/auto_client/app.py", line 15, in ssh
    ssh.connect(hostname=hostname, port=settings.SSH_PORT, username=settings.SSH_USER, password=settings.SSH_PWD)
  File "E:\Python3\lib\site-packages\paramiko\client.py", line 368, in connect
    raise NoValidConnectionsError(errors)
paramiko.ssh_exception.NoValidConnectionsError: [Errno None] Unable to connect to port 22 on 127.0.0.1

